Workbook

Sheet Dashboard PRO
A1: Dashboard PRO - Hofakkers 44
A3: Maandelijkse cashflow
A4: Netto inkomen per maand | B4: =Maandbegroting!D10 -> 5750
A5: Vaste lasten per maand (wonen + verzekeringen + vervoer) | B5: =Maandbegroting!D19+Maandbegroting!D25+Maandbegroting!D32 -> 1000
A6: Variabele lasten per maand (boodschappen + vrijetijd) | B6: =Maandbegroting!D40+Maandbegroting!D45 -> 1225
A7: Sparen & beleggen per maand | B7: =Maandbegroting!D50 -> 1100
A8: Totaal uitgaven incl. sparen | B8: =B5+B6+B7 -> 3325
A9: Ruimte per maand (incl. sparen) | B9: =B4-B8 -> 2425
A10: Ruimte per maand excl. sparen | B10: =B4-(B5+B6) -> 3525
A12: Eenmalige projectkosten
A13: Verbouwing (totaal) | B13: ='Verbouwing begroting'!F3 -> 56975
A14: Inboedel (totaal) | B14: ='Inboedel begroting'!F3 -> 16900
A15: Projectkosten samen (verbouwing + inboedel) | B15: ='Spaargeld + verbouwing'!C24 -> 73875
A16: Benodigd geld woning (aankoopkosten + project) | B16: ='Spaargeld + verbouwing'!C26 -> 80875
A17: Benodigd per persoon | B17: ='Spaargeld + verbouwing'!C27 -> 40437.5
A19: Vermogen & buffer na verbouwing
A20: Totaal sparen + beleggen nu | B20: ='Spaargeld + verbouwing'!B13 -> 235000
A21: Vermogen Patrick na verbouwing | B21: ='Spaargeld + verbouwing'!C30 -> 34562.5
A22: Vermogen Willianne na verbouwing | B22: ='Spaargeld + verbouwing'!C31 -> 119562.5
A23: Samen vermogen na verbouwing | B23: ='Spaargeld + verbouwing'!C32 -> 154125
A25: Kengetallen woning & verbouwing
A26: BG woon/keuken zonder uitbouw (m²) | B26: ='Verbouwing begroting'!J3 -> 40
A27: Uitbouw woon/keuken (m²) | B27: ='Verbouwing begroting'!J4 -> 20
A28: Totale woon/keuken na uitbouw (m²) | B28: ='Verbouwing begroting'!J5 -> 60
A29: Vloerverwarming m² | B29: ='Verbouwing begroting'!J6 -> 60

Sheet Maandbegroting
A1: Maandbegroting - overzicht per categorie
A2: INKOMSTEN & TOESLAGEN
A3: INKOMSTEN | B3: Willianne | D3: 2700 | G3: OVERZICHT
B4: Vakantiegeld | D4: =D3/12 -> 225
B5: 13 de maand | D5: =D3/12 -> 225
B6: Patrick | D6: 2700
B7: reiskosten vergoeding Patrick | D7: 350 | G7: Totaal inkomsten (maand) | I7: =D10 -> 5750 | K7: Vakantiegeld + 13de | L7: Willianne | M7: 5000
B8: Vakantiegeld | D8: =D5 -> 225 | K8: Vakantiegeld + 13de | L8: Patrick | M8: 5000
B9: 13 de maand | D9: =D4 -> 225 | K9: Bonus Patrick per jaar | M9: 1000
B10: totaal inkomen | D10: =SUM(D3:D9)-D4-D5-D8-D9 -> 5750 | G10: Totaal vaste lasten (maand) | I10: =D18+D32+D25 -> 3075
G11: Totaal variabele lasten (maand) | I11: =D40+D45 -> 1225 | K11: Extra inkomen per jaar | M11: =M7+M8+M9 -> 11000
A12: VASTE LASTEN | G12: Netto maand (Inkomen - Uitgaven) | I12: =I7-I10-I11 -> 1450 | K12: Extra inkomen per maand | M12: =M11/12 -> 916.66667
A13: WONEN | B13: Hypotheek / Rente | D13: 1600
B14: Onderhoud en belasting | D14: 200 | G14: Sparen + beleggen | I14: =D50 -> 1100
B15: Energie (gas/elec) | D15: 150 | J15: Met vakantiegeld en bonussen
B16: Water | D16: 25 | G16: Buffer in uitgaven | I16: =I12-I14 -> 350 | J16: =I16+M12 -> 1266.6667
B17: Internet / TV / Vast | D17: 100
B18: Wonen kosten | D18: =SUM(D13:D17) -> 2075
G19: jaarinkomen Willianne (netto) | H19: =M7+12*D3 -> 37400
A20: VERZEKERINGEN | G20: Jaarinkomen Patrick (netto) | H20: =M8+M9+12*D6 -> 38400
B21: Inboedelverzekering | D21: 20 | H21: =SUM(H19:H20) -> 75800
B22: Zorgverzekering P1 | D22: 150
B23: Zorgverzekering P2 | D23: 150 | G23: Totaal geschatte kosten per jaar | H23: =(I11+I10)*12 -> 51600
B24: Reis, levensverzekering erc | D24: 30
B25: Verzekering kosten | D25: =SUM(D20:D24) -> 350 | G25: Totaal over per jaar | H25: =H21-H23 -> 24200
A27: VERVOER | B27: Autoverzekering | D27: -
B28: Wegenbelasting | D28: 100
B29: Autoverzekering | D29: 100
B30: Brandstof | D30: 300
B31: Onderhoud auto | D31: 150
B32: Totaal vervoerkosten | D32: =SUM(D28:D31) -> 650
A34: VARIABELE LASTEN & SPAREN
A35: BOODSCHAPPEN | B35: Boodschappen | D35: 500
A36: HUISHOUD | B36: Overige aankopen | D36: 50
A37: PERSOONLIJK | B37: Willianne kleding | D37: 100
B38: Patrick Kleding | D38: 100
B39: Sport / Abonnementen | D39: 75
B40: Totaal lasten | D40: =SUM(D35:D39) -> 825
A42: VRIJETIJD | B42: Eten/drinken buiten de deur | D42: 200
B43: Abonnementen (Netflix/Spotify/etc.) | D43: 50
...

Sheet Spaargeld + verbouwing
A1: Patrick | E1: Willianne
A3: privé bankrekening | B3: 15000 | D3: privé bankrekening | F3: 10000
A4: spaarrekening | B4: 15000 | D4: spaarrekening | F4: 150000
A5: Beleggen | B5: 45000 | D5: Beleggen | F5: 0
A7: Totaal vermogen | B7: =SUM(B3:B6) -> 75000 | F7: =SUM(F3:F6) -> 160000
A10: Samen vermogen
A11: Sparen | B11: =B3+B4+F3+F4 -> 190000
A12: Beleggen | B12: =B5 -> 45000
B13: =SUM(B11:B12) -> 235000
A15: Begroting kosten - Hofakkers 44
A17: Hypotheekadvies | C17: 2100
A18: Notaris en bankkosten | C18: 3400
A19: Makelaarkosten | C19: 1500
A20: Totaal kosten aankoop | C20: =C17+C18+C19 -> 7000
A22: Begroting voor verbouwing | C22: ='Verbouwing begroting'!F3 -> 56975
A23: Begroting voor Inboedel aankopen | C23: ='Inboedel begroting'!F3 -> 16900
A24: Totaal | C24: =SUM(C22:C23) -> 73875
A26: Benodigd geld woning | C26: =C20+C24 -> 80875
A27: Verdeling kosten per persoon | C27: =C26/2 -> 40437.5
A29: Vermogen per persoon na verbouwing
A30: Patrick | C30: =B7-C27 -> 34562.5
A31: Willianne | C31: =F7-C27 -> 119562.5
B32: Totaal | C32: =SUM(C30:C31) -> 154125

Sheet Verbouwing begroting
A1: Verbouwingsbegroting Hofakkers 44 | I1: Parameters begane grond (m²)
A2: Categorie | B2: Post | C2: Aantal | D2: Eenheid | E2: Kosten per eenheid (€) | F2: Totaal (€) | G2: Opmerking
A3: Totale verwachting kosten | F3: =F11+F16+F22+F27+F33+F38 -> 56975 | I3: BG woon/keuken zonder uitbouw (m²) | J3: 40
A4: Uitbouw | I4: Uitbouw woon/keuken (m²) | J4: 20
B5: Uitbouw casco (materiaal, hout, isolatie, kozijnen) | C5: =J4 -> 20 | D5: m² | E5: 500 | F5: =C5*E5 -> 10000 | I5: Totaal woon/keuken (m²) | J5: =J3+J4 -> 60
B6: Fundering / vloerconstructie extra | C6: 1 | D6: post | E6: 1000 | F6: =C6*E6 -> 1000 | I6: Vloerverwarming (m²) | J6: =J5 -> 60
B7: Schuifpui + glas HR++ | C7: 1 | D7: stuks | E7: 2500 | F7: =C7*E7 -> 2500
B8: Extra elektra (spots, stopcontacten, loze leidingen) | C8: 1 | D8: post | E8: 500 | F8: =C8*E8 -> 500
B9: Aansluitwerk | C9: 1 | D9: post | E9: 1000 | F9: =C9*E9 -> 1000
B10: Stucwerk wanden/plafond uitbouw | C10: =J4 -> 20 | D10: m² | E10: 50 | F10: =C10*E10 -> 1000
E11: Totaal uitbouw | F11: =SUM(F5:F10) -> 16000
A12: Vloeren & vloerverwarming
B13: Nieuwe vloer begane grond (PVC/laminaat incl. leggen) | C13: =J5 -> 60 | D13: m² | E13: 50 | F13: =C13*E13 -> 3000
B14: Elektrische vloerverwarming (woonkamer/keuken) | C14: =J6 -> 60 | D14: m² | E14: 50 | F14: =C14*E14 -> 3000
B15: Plinten / afwerking vloer | C15: =ROUND(J5*1.3,0) -> 78 | D15: m¹ | E15: 12.5 | F15: =C15*E15 -> 975 | G15: Schatting m¹ plinten ≈ 1,3 x vloer-m²
E16: Totaal Vloer | F16: =SUM(F13:F15) -> 6975
A17: Keuken met kookeiland
B18: Nieuwe keuken incl. kookeiland (kasten + apparatuur) | C18: 1 | D18: stuks | E18: 17500 | F18: =C18*E18 -> 17500
B19: Sloop oude keuken + afvoer | C19: 1 | D19: post | E19: 1000 | F19: =C19*E19 -> 1000
B20: Extra elektra (inductie, groepen, kookgroep, spots) | C20: 1 | D20: post | E20: 2000 | F20: =C20*E20 -> 2000
B21: Loodgieter (verleggen water/afvoer) | C21: 1 | D21: post | E21: 1500 | F21: =C21*E21 -> 1500
E22: Totaal keuken | F22: =SUM(F18:F21) -> 22000
A23: Schilder- en behangwerk binnen
B24: Muren + plafonds schilderen verf (zelf doen + hulp) | C24: 1 | D24: Post | E24: 1200 | F24: =C24*E24 -> 1200
B25: Behang / renovlies + sausen | C25: 1 | D25: Post | E25: 1100 | F25: =C25*E25 -> 1100
B26: Schuur- en voorbehandeling (zelf doen) | C26: 1 | D26: post | E26: 200 | F26: =C26*E26 -> 200
E27: Toaal schilderwerk | F27: =SUM(F24:F26) -> 2500
A28: Badkamer & toilet
B29: Nieuw badkamermeubel + spiegelkast | C29: 1 | D29: stuks | E29: 700 | F29: =C29*E29 -> 700
B30: Toiletruimte: tegels + stuc + afvoer oude tegels | C30: 1 | D30: stuks | E30: 800 | F30: =C30*E30 -> 800
B31: Toiletruimte: Wastafel meubel | C31: 1 | D31: stuks | E31: 300 | F31: =C31*E31 -> 300
B32: Badkameraccessoires, zeepbakjes etc. | C32: 1 | D32: post | E32: 200 | F32: =C32*E32 -> 200
E33: Totaal Sanitair | F33: =SUM(F29:F32) -> 2000
A34: Overig & reserve
A35: Overig | B35: Verlichting door hele huis (spots, lampen,) | C35: 1 | D35: post | E35: 1500 | F35: =C35*E35 -> 1500
A36: Overig | B36: Kleine materialen (schroeven, kitten, gips, gereedschap) | C36: 1 | D36: post | E36: 1000 | F36: =C36*E36 -> 1000
A37: Reserve | B37: Onvoorzien verbouwing en buffer in budget (ca. 10% verbouwkosten) | E37: 5000 | F37: 5000
E38: Totaal Reserve posten | F38: =SUM(F35:F37) -> 7500

Sheet Inboedel begroting
A1: Inboedelbegroting (2 personen)
A2: Categorie | B2: Post | C2: Aantal | D2: Eenheid | E2: Kosten per eenheid (€) | F2: Totaal (€) | G2: Opmerking
A3: Totaal kosten | F3: =F55+F49+F42+F36+F29+F20+F13 -> 16900
A4: Woonkamer
A5: Woonkamer | B5: Bank (3-zits) | C5: 1 | D5: stuks | E5: 1000 | F5: =C5*E5 -> 1000
A6: Woonkamer | B6: Fauteuil / extra stoel | C6: 1 | D6: stuks | E6: 250 | F6: =C6*E6 -> 250
A7: Woonkamer | B7: Salontafel | C7: 1 | D7: stuks | E7: 200 | F7: =C7*E7 -> 200
A8: Woonkamer | B8: TV-meubel | C8: 1 | D8: stuks | E8: 300 | F8: =C8*E8 -> 300
A9: Woonkamer | B9: TV (50–55 inch) | C9: 1 | D9: stuks | E9: 600 | F9: =C9*E9 -> 600
A10: Woonkamer | B10: Vloerkleed | C10: 1 | D10: stuks | E10: 150 | F10: =C10*E10 -> 150
A11: Woonkamer | B11: Gordijnen / raamdecoratie | C11: 1 | D11: post | E11: 500 | F11: =C11*E11 -> 500
A12: Woonkamer | B12: Staande / hanglampen & verlichting | C12: 1 | D12: post | E12: 400 | F12: =C12*E12 -> 400
E13: Totaal woonkamer | F13: =SUM(F5:F12) -> 3400
A14: Keukeninrichting
A15: Eethoek | B15: Eettafel | C15: 1 | D15: stuks | E15: 700 | F15: =C15*E15 -> 700
A16: Eethoek | B16: Eetkamerstoelen | C16: 6 | D16: stuks | E16: 100 | F16: =C16*E16 -> 600
A17: Keuken | B17: Servies, bestek, glazen, pannen | C17: 1 | D17: set | E17: 1000 | F17: =C17*E17 -> 1000
A18: Keuken | B18: Kleine apparaten (waterkoker, koffiezet, broodrooster, mixer) | C18: 1 | D18: set | E18: 1500 | F18: =C18*E18 -> 1500 | G18: Kitchenaid + koffie al 1k. Is een keuze
A19: Keuken | B19: Keukentextiel & opbergboxen | C19: 1 | D19: post | E19: 200 | F19: =C19*E19 -> 200
E20: Totaal keuken | F20: =SUM(F15:F19) -> 4000
A21: Slaapkamer (hoofdslaapkamer)
A22: Slaapkamer | B22: Bedframe 2-persoons | C22: 1 | D22: stuks | E22: 500 | F22: =C22*E22 -> 500
A23: Slaapkamer | B23: Matras 2-persoons | C23: 1 | D23: stuks | E23: 1000 | F23: =C23*E23 -> 1000
A24: Slaapkamer | B24: Lattenbodem / bedbodem | C24: 1 | D24: stuks | E24: 300 | F24: =C24*E24 -> 300
A25: Slaapkamer | B25: Nachtkastjes | C25: 2 | D25: stuks | E25: 100 | F25: =C25*E25 -> 200
A26: Slaapkamer | B26: Kledingkast | C26: 1 | D26: stuks | E26: 500 | F26: =C26*E26 -> 500
A27: Slaapkamer | B27: Dekbedden, kussens, beddengoed | C27: 1 | D27: set | E27: 300 | F27: =C27*E27 -> 300
A28: Slaapkamer | B28: Gordijnen / raamdecoratie | C28: 1 | D28: post | E28: 200 | F28: =C28*E28 -> 200
E29: Totaal slaapkamer | F29: =SUM(F22:F28) -> 3000
A30: Zolder / Logeerkamer + Werkkamer
A31: Zolder / Logeerkamer | B31: Bed (1- of 2-persoons) | C31: 1 | D31: stuks | E31: 300 | F31: =C31*E31 -> 300 | G31: Kan later
A32: Zolder / Logeerkamer | B32: Matras | C32: 1 | D32: stuks | E32: 200 | F32: =C32*E32 -> 200 | G32: kan later
A33: Werkkamer | B33: Bureau | C33: 1 | D33: stuks | E33: 300 | F33: =C33*E33 -> 300 | G33: Voor willianne -> Vergoeding werk voor Patrick
A34: Werkkamer | B34: Bureaustoel | C34: 1 | D34: stuks | E34: 200 | F34: =C34*E34 -> 200 | G34: Voor willianne -> Vergoeding werk voor Patrick
A35: Werkkamer | B35: Kast / opbergrek | C35: 1 | D35: stuks | E35: 200 | F35: =C35*E35 -> 200
E36: Totaal restkamers | F36: =SUM(F31:F35) -> 1200
A37: Badkamer & toilet
A38: Badkamer | B38: Handdoeken set + gastendoekjes | C38: 1 | D38: set | E38: 250 | F38: =C38*E38 -> 250
A39: Badkamer | B39: Badkameraccessoires (prullenbak, zeeppomp, matten, etc.) | C39: 1 | D39: post | E39: 250 | F39: =C39*E39 -> 250
A40: Badkamer | B40: Föhn, weegschaal, kleine spullen | C40: 1 | D40: post | E40: 150 | F40: =C40*E40 -> 150
...

Sheet Sparen & Beleggen
A1: Sparen & Beleggen - Projectie per maand | E1: Inleg totaal | F1: Rendement totaal | G1: Eindsaldo totaal
D2: Saldo na 10 jaar | E2: =SUM(C9:C18) -> 60000 | F2: =SUM(D9:D18) -> 15472.009 | G2: =E18 -> 75472.009
A3: Startwaarde | B3: 0 | D3: Saldo na 20 jaar | E3: =SUM(C10:C19)+E2 -> 120000 | F3: =G3-E3 -> 78403.305 | G3: =E28 -> 198403.31
A4: Maandelijkse inleg (totaal) | B4: =Maandbegroting!D49 -> 500 | D4: Saldo na 30 jaar | E4: =SUM(C11:C20)+E3 -> 180000 | F4: =G4-E4 -> 218645.43 | G4: =E38 -> 398645.43
A5: Verwacht jaarlijks rendement (%) | B5: 0.05 | D5: Saldo na 40 jaar | E5: =SUM(C12:C21)+E4 -> 240000 | F5: =G5-E5 -> 484818.76 | G5: =E48 -> 724818.76
A6: Periode (jaren) | B6: 30 | D6: Saldo na 50 jaar | E6: =SUM(C13:C22)+E5 -> 300000 | F6: =G6-E6 -> 956120.74 | G6: =E58 -> 1256120.7
A8: Jaar | B8: Beginwaarde (€) | C8: Inleg (€) | D8: Rendement (€) | E8: Eindwaarde (€)
A9: 1 | B9: =B3 -> 0 | C9: =$B$4*12 -> 6000 | D9: =C9*(B5/100) -> 3 | E9: =B9+C9+D9 -> 6003
A10: 2 | B10: =E9 -> 6003 | C10: =$B$4*12 -> 6000 | D10: =B10*($B$5) -> 300.15 | E10: =B10+C10+D10 -> 12303.15
A11: 3 | B11: =E10 -> 12303.15 | C11: =$B$4*12 -> 6000 | D11: =B11*($B$5) -> 615.1575 | E11: =B11+C11+D11 -> 18918.308
A12: 4 | B12: =E11 -> 18918.308 | C12: =$B$4*12 -> 6000 | D12: =B12*($B$5) -> 945.91538 | E12: =B12+C12+D12 -> 25864.223
A13: 5 | B13: =E12 -> 25864.223 | C13: =$B$4*12 -> 6000 | D13: =B13*($B$5) -> 1293.2111 | E13: =B13+C13+D13 -> 33157.434
A14: 6 | B14: =E13 -> 33157.434 | C14: =$B$4*12 -> 6000 | D14: =B14*($B$5) -> 1657.8717 | E14: =B14+C14+D14 -> 40815.306
A15: 7 | B15: =E14 -> 40815.306 | C15: =$B$4*12 -> 6000 | D15: =B15*($B$5) -> 2040.7653 | E15: =B15+C15+D15 -> 48856.071
A16: 8 | B16: =E15 -> 48856.071 | C16: =$B$4*12 -> 6000 | D16: =B16*($B$5) -> 2442.8036 | E16: =B16+C16+D16 -> 57298.875
A17: 9 | B17: =E16 -> 57298.875 | C17: =$B$4*12 -> 6000 | D17: =B17*($B$5) -> 2864.9437 | E17: =B17+C17+D17 -> 66163.818
A18: 10 | B18: =E17 -> 66163.818 | C18: =$B$4*12 -> 6000 | D18: =B18*($B$5) -> 3308.1909 | E18: =B18+C18+D18 -> 75472.009
A19: 11 | B19: =E18 -> 75472.009 | C19: =$B$4*12 -> 6000 | D19: =B19*($B$5) -> 3773.6005 | E19: =B19+C19+D19 -> 85245.61
A20: 12 | B20: =E19 -> 85245.61 | C20: =$B$4*12 -> 6000 | D20: =B20*($B$5) -> 4262.2805 | E20: =B20+C20+D20 -> 95507.89
A21: 13 | B21: =E20 -> 95507.89 | C21: =$B$4*12 -> 6000 | D21: =B21*($B$5) -> 4775.3945 | E21: =B21+C21+D21 -> 106283.28
... A58: 50 | B58: =E57 -> 1190591.2 | C58: =$B$4*12 -> 6000 | D58: =B58*($B$5) -> 59529.559 | E58: =B58+C58+D58 -> 1256120.7

Sheet Hypotheek
A1: Periode | B1: Totale schuld | C1: Te betalen rente | D1: Te betalen aflossing | E1: Restschuld | F1: Totale maandbedrag
A2: 1 | B2: =I3 -> 365000 | C2: =IFERROR(B2*$I$4/12,"") -> 1025.0417 | D2: =IFERROR(F2-C2,"") -> 587.59946 | E2: =IF(A2<>"",$I$6,"") -> 1612.6411 | F2: =IF(A2<>"",$I$6,"") -> 1612.6411 | H2: Gegevens Annuïteitenhypotheek
A3: 2 | B3: =IFERROR(IF(B2-D2>=0.01,B2-D2,""),"") -> 364412.4 | C3: =IFERROR(B3*$I$4/12,"") -> 1023.3915 | D3: =IFERROR(F3-C3,"") -> 589.24964 | E3: =IF(A3<>"",$I$6,"") -> 1612.6411 | F3: =IF(A3<>"",$I$6,"") -> 1612.6411 | H3: Hoofdsom | I3: 365000
A4: 3 | B4: =IFERROR(IF(B3-D3>=0.01,B3-D3,""),"") -> 363823.15 | C4: =IFERROR(B4*$I$4/12,"") -> 1021.7367 | D4: =IFERROR(F4-C4,"") -> 590.90444 | E4: =IF(A4<>"",$I$6,"") -> 1612.6411 | F4: =IF(A4<>"",$I$6,"") -> 1612.6411 | H4: Rentepercentage | I4: 0.0337
A5: 4 | B5: =IFERROR(IF(B4-D4>=0.01,B4-D4,""),"") -> 363232.25 | C5: =IFERROR(B5*$I$4/12,"") -> 1020.0772 | D5: =IFERROR(F5-C5,"") -> 592.5639 | E5: =IF(A5<>"",$I$6,"") -> 1612.6411 | F5: =IF(A5<>"",$I$6,"") -> 1612.6411 | H5: Looptijd in maanden | I5: 360
A6: 5 | B6: =IFERROR(IF(B5-D5>=0.01,B5-D5,""),"") -> 362639.68 | C6: =IFERROR(B6*$I$4/12,"") -> 1018.4131 | D6: =IFERROR(F6-C6,"") -> 594.22802 | E6: =IF(A6<>"",$I$6,"") -> 1612.6411 | F6: =IF(A6<>"",$I$6,"") -> 1612.6411 | H6: Totaal maandelijks | I6: =-PMT(I4/12,I5,I3) -> 1612.6411
A7: 6 | B7: =IFERROR(IF(B6-D6>=0.01,B6-D6,""),"") -> 362045.45 | C7: =IFERROR(B7*$I$4/12,"") -> 1016.7443 | D7: =IFERROR(F7-C7,"") -> 595.89681 | E7: =IF(A7<>"",$I$6,"") -> 1612.6411 | F7: =IF(A7<>"",$I$6,"") -> 1612.6411 | H7: Totaal annuïteiten | I7: =SUMIF(B2:B601,">=0",F2:F601) -> 580550.81
A8: 7 | B8: =IFERROR(IF(B7-D7>=0.01,B7-D7,""),"") -> 361449.56 | C8: =IFERROR(B8*$I$4/12,"") -> 1015.0708 | D8: =IFERROR(F8-C8,"") -> 597.57029 | E8: =IF(A8<>"",$I$6,"") -> 1612.6411 | F8: =IF(A8<>"",$I$6,"") -> 1612.6411
A9: 8 | B9: =IFERROR(IF(B8-D8>=0.01,B8-D8,""),"") -> 360851.99 | C9: =IFERROR(B9*$I$4/12,"") -> 1013.3927 | D9: =IFERROR(F9-C9,"") -> 599.24846 | E9: =IF(A9<>"",$I$6,"") -> 1612.6411 | F9: =IF(A9<>"",$I$6,"") -> 1612.6411 | H9: Totaal betaalde rente | I9: =SUM(C:C) -> 215550.81
A10: 9 | B10: =IFERROR(IF(B9-D9>=0.01,B9-D9,""),"") -> 360252.74 | C10: =IFERROR(B10*$I$4/12,"") -> 1011.7098 | D10: =IFERROR(F10-C10,"") -> 600.93135 | E10: =IF(A10<>"",$I$6,"") -> 1612.6411 | F10: =IF(A10<>"",$I$6,"") -> 1612.6411 | H10: totaal betaalde aflossing | I10: =SUM(D:D) -> 365000
A11: 10 | B11: =IFERROR(IF(B10-D10>=0.01,B10-D10,""),"") -> 359651.81 | C11: =IFERROR(B11*$I$4/12,"") -> 1010.0222 | D11: =IFERROR(F11-C11,"") -> 602.61897 | E11: =IF(A11<>"",$I$6,"") -> 1612.6411 | F11: =IF(A11<>"",$I$6,"") -> 1612.6411 | H11: totaal betaald | I11: =I9+I10 -> 580550.81
A12: 11 | B12: =IFERROR(IF(B11-D11>=0.01,B11-D11,""),"") -> 359049.19 | C12: =IFERROR(B12*$I$4/12,"") -> 1008.3298 | D12: =IFERROR(F12-C12,"") -> 604.31132 | E12: =IF(A12<>"",$I$6,"") -> 1612.6411 | F12: =IF(A12<>"",$I$6,"") -> 1612.6411
A13: 12 | B13: =IFERROR(IF(B12-D12>=0.01,B12-D12,""),"") -> 358444.88 | C13: =IFERROR(B13*$I$4/12,"") -> 1006.6327 | D13: =IFERROR(F13-C13,"") -> 606.00843 | E13: =IF(A13<>"",$I$6,"") -> 1612.6411 | F13: =IF(A13<>"",$I$6,"") -> 1612.6411
A14: 13 | B14: =IFERROR(IF(B13-D13>=0.01,B13-D13,""),"") -> 357838.87 | C14: =IFERROR(B14*$I$4/12,"") -> 1004.9308 | D14: =IFERROR(F14-C14,"") -> 607.7103 | E14: =IF(A14<>"",$I$6,"") -> 1612.6411 | F14: =IF(A14<>"",$I$6,"") -> 1612.6411
A15: 14 | B15: =IFERROR(IF(B14-D14>=0.01,B14-D14,""),"") -> 357231.16 | C15: =IFERROR(B15*$I$4/12,"") -> 1003.2242 | D15: =IFERROR(F15-C15,"") -> 609.41696 | E15: =IF(A15<>"",$I$6,"") -> 1612.6411 | F15: =IF(A15<>"",$I$6,"") -> 1612.6411
A16: 15 | B16: =IFERROR(IF(B15-D15>=0.01,B15-D15,""),"") -> 356621.74 | C16: =IFERROR(B16*$I$4/12,"") -> 1001.5127 | D16: =IFERROR(F16-C16,"") -> 611.1284 | E16: =IF(A16<>"",$I$6,"") -> 1612.6411 | F16: =IF(A16<>"",$I$6,"") -> 1612.6411
A17: 16 | B17: =IFERROR(IF(B16-D16>=0.01,B16-D16,""),"") -> 356010.61 | C17: =IFERROR(B17*$I$4/12,"") -> 999.79647 | D17: =IFERROR(F17-C17,"") -> 612.84465 | E17: =IF(A17<>"",$I$6,"") -> 1612.6411 | F17: =IF(A17<>"",$I$6,"") -> 1612.6411
A18: 17 | B18: =IFERROR(IF(B17-D17>=0.01,B17-D17,""),"") -> 355397.77 | C18: =IFERROR(B18*$I$4/12,"") -> 998.0754 | D18: =IFERROR(F18-C18,"") -> 614.56573 | E18: =IF(A18<>"",$I$6,"") -> 1612.6411 | F18: =IF(A18<>"",$I$6,"") -> 1612.6411
A19: 18 | B19: =IFERROR(IF(B18-D18>=0.01,B18-D18,""),"") -> 354783.2 | C19: =IFERROR(B19*$I$4/12,"") -> 996.34949 | D19: =IFERROR(F19-C19,"") -> 616.29163 | E19: =IF(A19<>"",$I$6,"") -> 1612.6411 | F19: =IF(A19<>"",$I$6,"") -> 1612.6411
A20: 19 | B20: =IFERROR(IF(B19-D19>=0.01,B19-D19,""),"") -> 354166.91 | C20: =IFERROR(B20*$I$4/12,"") -> 994.61874 | D20: =IFERROR(F20-C20,"") -> 618.02238 | E20: =IF(A20<>"",$I$6,"") -> 1612.6411 | F20: =IF(A20<>"",$I$6,"") -> 1612.6411
A21: 20 | B21: =IFERROR(IF(B20-D20>=0.01,B20-D20,""),"") -> 353548.89 | C21: =IFERROR(B21*$I$4/12,"") -> 992.88313 | D21: =IFERROR(F21-C21,"") -> 619.758 | E21: =IF(A21<>"",$I$6,"") -> 1612.6411 | F21: =IF(A21<>"",$I$6,"") -> 1612.6411
A22: 21 | B22: =IFERROR(IF(B21-D21>=0.01,B21-D21,""),"") -> 352929.13 | C22: =IFERROR(B22*$I$4/12,"") -> 991.14264 | D22: =IFERROR(F22-C22,"") -> 621.49848 | E22: =IF(A22<>"",$I$6,"") -> 1612.6411 | F22: =IF(A22<>"",$I$6,"") -> 1612.6411
A23: 22 | B23: =IFERROR(IF(B22-D22>=0.01,B22-D22,""),"") -> 352307.63 | C23: =IFERROR(B23*$I$4/12,"") -> 989.39727 | D23: =IFERROR(F23-C23,"") -> 623.24386 | E23: =IF(A23<>"",$I$6,"") -> 1612.6411 | F23: =IF(A23<>"",$I$6,"") -> 1612.6411
... A361: 360 | B361: =IFERROR(IF(B360-D360>=0.01,B360-D360,""),"") -> 1608.125 | C361: =IFERROR(B361*$I$4/12,"") -> 4.516151 | D361: =IFERROR(F361-C361,"") -> 1608.125 | E361: =IF(A361<>"",$I$6,"") -> 1612.6411 | F361: =IF(A361<>"",$I$6,"") -> 1612.6411
